Workbook
Name RL_Actif_Net: Paramètres!$C$19
Name RL_Age_Prix: Paramètres!$C$12
Name RL_Choc_Spread: Paramètres!$C$8
Name RL_Choc_Taux: Paramètres!$C$7
Name RL_Confiance: Paramètres!$C$6
Name RL_Date: Paramètres!$C$18
Name RL_Ecart_Contributions: Contrôles!$C$8
Name RL_ES_Apres: Comité!$D$10
Name RL_ES_Initial: Comité!$C$10
Name RL_Horodatage: Contrôles!$C$13
Name RL_ISIN_Vente: Paramètres!$C$9
Name RL_Liste_ISIN: Positions!$B$7:$B$173
Name RL_Montant_Vente: Paramètres!$C$10
Name RL_NAV: Positions!$J$175
Name RL_Poids_Apres: Positions!$U$7:$U$174
Name RL_Sensibilite_Spread: Positions!$AF$7:$AF$174
Name RL_Sensibilites: Positions!$M$7:$O$174
Name RL_Seuil_Cumul_40: Paramètres!$C$16
Name RL_Seuil_Emetteur_10: Paramètres!$C$15
Name RL_Seuil_Emetteur_5: Paramètres!$C$14
Name RL_Seuil_Ligne: Paramètres!$C$13
Name RL_Spread_Revue: Paramètres!$C$11
Name RL_Statut_VBA: Contrôles!$E$13
Name RL_Tableau_Positions: Positions!$B$6:$AC$174
Name RL_Valide: Paramètres!$C$20
Name RL_VaR_Apres: Comité!$D$9
Name RL_VaR_Initial: Comité!$C$9
Name RL_Variations: Historique!$D$7:$G$1006
Name RL_Zone_Comite: Comité!$B$2:$H$45

Sheet Comité
B2: RiskLens : synthèse pour le comité des risques
B3: R-co Conviction Credit Euro, inventaire publié au 30/06/2025. Section obligations à taux fixe EUR, 167 lignes modélisées. Risque à un jour sur chocs observés : courbe BCE, spread crédit Bundesbank.
B5: Indicateur | C5: Initial | D5: Après vente | E5: Écart | G5: Premiers contributeurs à l'ES | H5: ES après (EUR)
B6: Valeur du portefeuille modélisé (EUR) | C6: =RL_NAV -> 2.5922268e+09 | D6: =RL_NAV -> 2.5922268e+09 | E6: =D6-C6 -> 0 | G6: =INDEX(Positions!$C$7:$C$173,MATCH(H6,Positions!$W$7:$W$173,0)) -> MALA HU 4.5 06-35 | H6: =LARGE(Positions!$W$7:$W$173,1) -> 793821.25
B7: Part de l'actif net publié du fonds | C7: =RL_NAV/RL_Actif_Net -> 0.66015837 | D7: =RL_NAV/RL_Actif_Net -> 0.66015837 | E7: =D7-C7 -> 0 | G7: =INDEX(Positions!$C$7:$C$173,MATCH(H7,Positions!$W$7:$W$173,0)) -> BUND DE 0.0 08-29 | H7: =LARGE(Positions!$W$7:$W$173,2) -> 765111.87
B8: Niveau de confiance | C8: =RL_Confiance -> 0.99 | D8: =RL_Confiance -> 0.99 | E8: =D8-C8 -> 0 | G8: =INDEX(Positions!$C$7:$C$173,MATCH(H8,Positions!$W$7:$W$173,0)) -> APIC PR 5.375 10-34 | H8: =LARGE(Positions!$W$7:$W$173,3) -> 709084.51
B9: VaR à 1 jour (EUR) | C9: =Calculs!I16 -> 20982292 | D9: =Calculs!J16 -> 20535074 | E9: =D9-C9 -> -447218.41 | G9: =INDEX(Positions!$C$7:$C$173,MATCH(H9,Positions!$W$7:$W$173,0)) -> VOLK WI 5.5 12-35 | H9: =LARGE(Positions!$W$7:$W$173,4) -> 597869.33
B10: Expected Shortfall à 1 jour (EUR) | C10: =Calculs!I17 -> 29274800 | D10: =Calculs!J17 -> 28675584 | E10: =D10-C10 -> -599215.69 | G10: =INDEX(Positions!$C$7:$C$173,MATCH(H10,Positions!$W$7:$W$173,0)) -> TEREGA 4.0 09-34 | H10: =LARGE(Positions!$W$7:$W$173,5) -> 559101.06
B11: VaR en % de la valeur | C11: =C9/RL_NAV -> 0.0080943118 | D11: =D9/RL_NAV -> 0.0079217889 | E11: =D11-C11 -> -0.00017252287 | G11: =INDEX(Positions!$C$7:$C$173,MATCH(H11,Positions!$W$7:$W$173,0)) -> EATO CA 3.802 05-36 | H11: =LARGE(Positions!$W$7:$W$173,6) -> 538687.33
B12: Duration du portefeuille | C12: =Calculs!I10+Calculs!I11+Calculs!I12 -> 4.899404 | D12: =Calculs!J10+Calculs!J11+Calculs!J12 -> 4.8407486 | E12: =D12-C12 -> -0.058655363 | G12: =INDEX(Positions!$C$7:$C$173,MATCH(H12,Positions!$W$7:$W$173,0)) -> WERF 3.625 02-32 | H12: =LARGE(Positions!$W$7:$W$173,7) -> 521813.23
B13: Stress linéaire (EUR) | C13: =Positions!Y175 -> 3.0556203e+08 | D13: =Positions!Z175 -> 3.0176083e+08 | E13: =D13-C13 -> -3801200.1 | G13: =INDEX(Positions!$C$7:$C$173,MATCH(H13,Positions!$W$7:$W$173,0)) -> ASK CHE 10.0 11-29 | H13: =LARGE(Positions!$W$7:$W$173,8) -> 470387.11
B14: Stress par revalorisation des flux (EUR) | C14: =Positions!AA175 -> 2.831167e+08 | D14: =Positions!AB175 -> 2.7971774e+08 | E14: =D14-C14 -> -3398955 | G14: =INDEX(Positions!$C$7:$C$173,MATCH(H14,Positions!$W$7:$W$173,0)) -> AUST PA 4.0 06-34 | H14: =LARGE(Positions!$W$7:$W$173,9) -> 470110
B15: Liquidités (EUR) | C15: =Positions!J174 -> 0 | D15: =Positions!S174 -> 20000000 | E15: =D15-C15 -> 20000000 | G15: =INDEX(Positions!$C$7:$C$173,MATCH(H15,Positions!$W$7:$W$173,0)) -> LAGA 4.75 06-30 | H15: =LARGE(Positions!$W$7:$W$173,10) -> 448258.09
B17: Stress appliqué | C17: ="Taux "&TEXT(RL_Choc_Taux,"+0;-0")&" pb, spreads "&TEXT(RL_Choc_Spread,"+0;-0")&" pb" -> Taux +100 pb, spreads +150 pb
B19: Vente simulée | C19: Valeur | G19: Contrôles | H19: Résultat
B20: Ligne vendue | C20: =INDEX(Positions!$C$7:$C$173,MATCH(RL_ISIN_Vente,RL_Liste_ISIN,0)) -> KLES PR 5.07 07-35 | G20: Lignes « À instruire » | H20: =COUNTIF(Inventaire!$W$7:$W$175,"À instruire") -> 2
B21: Montant vendu (EUR) | C21: =RL_Montant_Vente -> 20000000 | G21: Lignes « À examiner » | H21: =COUNTIF(Inventaire!$W$7:$W$175,"À examiner") -> 4
B22: ES par M EUR détenu sur cette ligne, avant vente | C22: =INDEX(Positions!$V$7:$V$173,MATCH(RL_ISIN_Vente,RL_Liste_ISIN,0))/INDEX(Positions!$J$7:$J$173,MATCH(RL_ISIN_Vente,RL_Liste_ISIN,0))*1000000 -> 29960.784 | G22: Lignes au-dessus du seuil de revue | H22: =COUNTIF(Positions!$AC$7:$AC$173,"OUI") -> 0
B23: Réduction d'ES par M EUR vendu | C23: =IF(RL_Montant_Vente>0,(C10-D10)/RL_Montant_Vente*1000000,0) -> 29960.784 | G23: Dispersion émetteurs | H23: =Émetteurs!$J$12 -> Aucun dépassement sur la section connue
B24: Référence : vente au prorata, par M EUR vendu | C24: =C10/RL_NAV*1000000 -> 11293.302 | G24: Rapprochements en écart | H24: =COUNTIF(Contrôles!$E$6:$E$11,"ÉCART") -> 0
B25: Efficacité relative au prorata | C25: =IF(C24>0,C23/C24,0) -> 2.6529694 | G25: Backtest (Kupiec) | H25: =Backtest!$H$12 -> Calibration non rejetée
B28: Contribution à l'ES par facteur | C28: Initial (EUR) | D28: Après vente (EUR)
B29: Taux 2 ans | C29: =RL_NAV*Calculs!I10*Calculs!I13 -> 1812072 | D29: =RL_NAV*Calculs!J10*Calculs!J13 -> 1806877.4
B30: Taux 5 ans | C30: =RL_NAV*Calculs!I11*Calculs!I14 -> 6351136.7 | D30: =RL_NAV*Calculs!J11*Calculs!J14 -> 6334827.7
B31: Taux 10 ans | C31: =RL_NAV*Calculs!I12*Calculs!I15 -> 3859657.4 | D31: =RL_NAV*Calculs!J12*Calculs!J15 -> 3741392.3
B32: Spread crédit | C32: =RL_NAV*Calculs!I21*Calculs!I22 -> 17251934 | D32: =RL_NAV*Calculs!J21*Calculs!J22 -> 16792487
B42: Périmètre : section taux fixe EUR de l'inventaire publié ; dérivés, autres sections et passifs exclus. Ce n'est ni la VaR du fonds ni un contrôle de ses limites.
B43: Mesure : taux et spread crédit. Le facteur de spread est un indice d'obligations d'entreprises allemandes (Bundesbank), bêta par ligne proportionnel au spread (DTS).
B44: Modèle : flux annuels théoriques, courbe AAA BCE interpolée 2/5/10 ans, spread constant ajusté au prix dirty ; options ignorées. ES à 99 % fondée sur 10 journées équivalentes.

Sheet Paramètres
B2: Paramètres
B3: Cellules jaunes : saisie. Les seuils sont des seuils de revue du prototype, pas des limites du fonds.
B5: Paramètre | C5: Valeur | D5: Commentaire
B6: Niveau de confiance | C6: 0.99 | D6: 95 % ou 99 %
B7: Choc parallèle de taux (pb) | C7: 100 | D7: De -300 à +300 pb
B8: Choc uniforme de spreads (pb) | C8: 150 | D8: De -200 à +500 pb ; non appliqué au souverain AAA
B9: Ligne à vendre (ISIN) | C9: FR0014010XH0 | D9: Liste déroulante ; vente réinvestie en liquidités, sans frais
B10: Montant de la vente (EUR) | C10: 20000000 | D10: Entre 0 et la valeur détenue sur la ligne
B11: Seuil de spread de revue (pb) | C11: 600 | D11: Au-delà : suivi crédit
B12: Ancienneté maximale d'un prix (jours) | C12: 5 | D12: Par rapport à la date de référence
B13: Seuil de revue par ligne | C13: 0.1 | D13: En % du portefeuille modélisé
B14: Seuil émetteur, règle 5/10/40 | C14: 0.05 | D14: En % de l'actif net publié
B15: Plafond émetteur, règle 5/10/40 | C15: 0.1 | D15: En % de l'actif net publié
B16: Plafond du cumul des émetteurs > 5 % | C16: 0.4 | D16: En % de l'actif net publié
B18: Date de référence | C18: 45838
B19: Actif net publié du fonds (EUR) | C19: 3.9266742e+09
B20: Validité des paramètres | C20: =IF(AND(OR(RL_Confiance=0.95,RL_Confiance=0.99),RL_Choc_Taux>=-300,RL_Choc_Taux<=300,RL_Choc_Spread>=-200,RL_Choc_Spread<=500,ISNUMBER(MATCH(RL_ISIN_Vente,RL_Liste_ISIN,0)),RL_Montant_Vente>=0,RL_Montant_Vente<=IFERROR(INDEX(Positions!$J$7:$J$173,MATCH(RL_ISIN_Vente,RL_Liste_ISIN,0)),0),RL_Spread_Revue>0,RL_Age_Prix>=0,RL_Seuil_Ligne>0,RL_Seuil_Emetteur_5>0,RL_Seuil_Emetteur_10>0,RL_Seuil_Cumul_40>0),"OK","À CORRIGER") -> OK
B22: Les chocs de stress sont hypothétiques et sans probabilité attribuée. Le module VBA facultatif ajoute une vérification indépendante et les exports.

Sheet Positions
B2: Positions modélisées
B3: 167 lignes de la section taux fixe EUR. Valeurs publiées ; spreads et sensibilités estimés par le modèle de flux (valeurs importées du moteur Python).
B6: ISIN | C6: Libellé | D6: Émetteur | E6: Échéance | F6: Coupon (%) | G6: Nominal (EUR) | H6: Prix clean | I6: Coupon couru (EUR) | J6: Valeur publiée (EUR) | K6: Prix dirty | L6: Spread calibré (pb) | M6: Sensibilité 2 ans | N6: Sensibilité 5 ans | O6: Sensibilité 10 ans | P6: Duration | Q6: Duration de spread | R6: Souverain AAA | S6: Montant après vente (EUR) | T6: Poids initial | U6: Poids après vente | V6: Contribution ES initiale (EUR) | W6: Contribution ES après (EUR) | X6: ES par M EUR détenu | Y6: Stress linéaire initial (EUR) | Z6: Stress linéaire après (EUR) | AA6: Stress revalorisé initial (EUR) | AB6: Stress revalorisé après (EUR) | AC6: Au-dessus du seuil de ligne | AD6: Écart flux / prix dirty | AE6: Bêta de spread | AF6: Sensibilité au facteur spread
B7: AT0000A3KDQ3 | C7: KOMM 4.25 04-31 | D7: KOMM | E7: 47939 | F7: 4.25 | G7: 19900000 | H7: 101.3925 | I7: 213175.34 | J7: 20390283 | K7: =J7/G7*100 -> 102.46373 | L7: 167.86978 | M7: 0.24601555 | N7: 4.2259686 | O7: 0.70300249 | P7: =SUM(M7:O7) -> 5.1749866 | Q7: =IF(R7="OUI",0,P7) -> 5.1749866 | R7: NON | S7: =IF(B7=RL_ISIN_Vente,J7-RL_Montant_Vente,J7) -> 20390283 | T7: =J7/RL_NAV -> 0.0078659332 | U7: =S7/RL_NAV -> 0.0078659332 | V7: =RL_NAV*T7*(M7*Calculs!$I$13+N7*Calculs!$I$14+O7*Calculs!$I$15+AF7*Calculs!$I$22) -> 282373.37 | W7: =RL_NAV*U7*(M7*Calculs!$J$13+N7*Calculs!$J$14+O7*Calculs!$J$15+AF7*Calculs!$J$22) -> 282373.37 | X7: =IF(S7>0,W7/S7*1000000,0) -> 13848.428 | Y7: =RL_NAV*T7*(P7*RL_Choc_Taux+Q7*RL_Choc_Spread)/10000 -> 2637986 | Z7: =RL_NAV*U7*(P7*RL_Choc_Taux+Q7*RL_Choc_Spread)/10000 -> 2637986 | AA7: =RL_NAV*T7*(1-SUMPRODUCT((Flux!$B$7:$B$926=B7)*Flux!$F$7:$F$926*EXP(-(RL_Choc_Taux+IF(Q7>0,RL_Choc_Spread,0))/10000*Flux!$D$7:$D$926))/K7) -> 2464033.3 | AB7: =RL_NAV*U7*(1-SUMPRODUCT((Flux!$B$7:$B$926=B7)*Flux!$F$7:$F$926*EXP(-(RL_Choc_Taux+IF(Q7>0,RL_Choc_Spread,0))/10000*Flux!$D$7:$D$926))/K7) -> 2464033.3 | AC7: =IF(U7>RL_Seuil_Ligne,"OUI","") | AD7: =SUMIF(Flux!$B$7:$B$926,B7,Flux!$F$7:$F$926)-K7 -> 0 | AE7: 1.5543498 | AF7: =Q7*AE7 -> 8.0437396
B8: AT000B122080 | C8: VOLK WI 0.875 03-26 | D8: VOLK WI | E8: 46104 | F8: 0.875 | G8: 10200000 | H8: 98.8085 | I8: 24696.58 | J8: 10103164 | K8: =J8/G8*100 -> 99.050623 | L8: 66.119016 | M8: 0.72826831 | N8: 0 | O8: 0 | P8: =SUM(M8:O8) -> 0.72826831 | Q8: =IF(R8="OUI",0,P8) -> 0.72826831 | R8: NON | S8: =IF(B8=RL_ISIN_Vente,J8-RL_Montant_Vente,J8) -> 10103164 | T8: =J8/RL_NAV -> 0.0038974844 | U8: =S8/RL_NAV -> 0.0038974844 | V8: =RL_NAV*T8*(M8*Calculs!$I$13+N8*Calculs!$I$14+O8*Calculs!$I$15+AF8*Calculs!$I$22) -> 11709.907 | W8: =RL_NAV*U8*(M8*Calculs!$J$13+N8*Calculs!$J$14+O8*Calculs!$J$15+AF8*Calculs!$J$22) -> 11709.907 | X8: =IF(S8>0,W8/S8*1000000,0) -> 1159.0337 | Y8: =RL_NAV*T8*(P8*RL_Choc_Taux+Q8*RL_Choc_Spread)/10000 -> 183945.35 | Z8: =RL_NAV*U8*(P8*RL_Choc_Taux+Q8*RL_Choc_Spread)/10000 -> 183945.35 | AA8: =RL_NAV*T8*(1-SUMPRODUCT((Flux!$B$7:$B$926=B8)*Flux!$F$7:$F$926*EXP(-(RL_Choc_Taux+IF(Q8>0,RL_Choc_Spread,0))/10000*Flux!$D$7:$D$926))/K8) -> 182280.94 | AB8: =RL_NAV*U8*(1-SUMPRODUCT((Flux!$B$7:$B$926=B8)*Flux!$F$7:$F$926*EXP(-(RL_Choc_Taux+IF(Q8>0,RL_Choc_Spread,0))/10000*Flux!$D$7:$D$926))/K8) -> 182280.94 | AC8: =IF(U8>RL_Seuil_Ligne,"OUI","") | AD8: =SUMIF(Flux!$B$7:$B$926,B8,Flux!$F$7:$F$926)-K8 -> 0 | AE8: 0.61221311 | AF8: =Q8*AE8 -> 0.44585541
B9: AT000B122296 | C9: VOLK WI 5.5 12-35 | D9: VOLK WI | E9: 49647 | F9: 5.5 | G9: 21300000 | H9: 102.195 | I9: 965288.29 | J9: 22732823 | K9: =J9/G9*100 -> 106.72687 | L9: 233.13591 | M9: 0.30335587 | N9: 0.88019326 | O9: 6.8010578 | P9: =SUM(M9:O9) -> 7.984607 | Q9: =IF(R9="OUI",0,P9) -> 7.984607 | R9: NON | S9: =IF(B9=RL_ISIN_Vente,J9-RL_Montant_Vente,J9) -> 22732823 | T9: =J9/RL_NAV -> 0.008769612 | U9: =S9/RL_NAV -> 0.008769612 | V9: =RL_NAV*T9*(M9*Calculs!$I$13+N9*Calculs!$I$14+O9*Calculs!$I$15+AF9*Calculs!$I$22) -> 597869.33 | W9: =RL_NAV*U9*(M9*Calculs!$J$13+N9*Calculs!$J$14+O9*Calculs!$J$15+AF9*Calculs!$J$22) -> 597869.33 | X9: =IF(S9>0,W9/S9*1000000,0) -> 26299.827 | Y9: =RL_NAV*T9*(P9*RL_Choc_Taux+Q9*RL_Choc_Spread)/10000 -> 4537816.5 | Z9: =RL_NAV*U9*(P9*RL_Choc_Taux+Q9*RL_Choc_Spread)/10000 -> 4537816.5 | AA9: =RL_NAV*T9*(1-SUMPRODUCT((Flux!$B$7:$B$926=B9)*Flux!$F$7:$F$926*EXP(-(RL_Choc_Taux+IF(Q9>0,RL_Choc_Spread,0))/10000*Flux!$D$7:$D$926))/K9) -> 4042749.2 | AB9: =RL_NAV*U9*(1-SUMPRODUCT((Flux!$B$7:$B$926=B9)*Flux!$F$7:$F$926*EXP(-(RL_Choc_Taux+IF(Q9>0,RL_Choc_Spread,0))/10000*Flux!$D$7:$D$926))/K9) -> 4042749.2 | AC9: =IF(U9>RL_Seuil_Ligne,"OUI","") | AD9: =SUMIF(Flux!$B$7:$B$926,B9,Flux!$F$7:$F$926)-K9 -> 0 | AE9: 2.1586658 | AF9: =Q9*AE9 -> 17.236098
B10: BE0002938190 | C10: GROU BR 4.0 05-33 | D10: GROU BR | E10: 48714 | F10: 4 | G10: 20000000 | H10: 104.15 | I10: 105205.48 | J10: 20935205 | K10: =J10/G10*100 -> 104.67603 | L10: 91.413757 | M10: 0.22856528 | N10: 3.1016111 | O10: 3.5597892 | P10: =SUM(M10:O10) -> 6.8899657 | Q10: =IF(R10="OUI",0,P10) -> 6.8899657 | R10: NON | S10: =IF(B10=RL_ISIN_Vente,J10-RL_Montant_Vente,J10) -> 20935205 | T10: =J10/RL_NAV -> 0.0080761473 | U10: =S10/RL_NAV -> 0.0080761473 | V10: =RL_NAV*T10*(M10*Calculs!$I$13+N10*Calculs!$I$14+O10*Calculs!$I$15+AF10*Calculs!$I$22) -> 270150.98 | W10: =RL_NAV*U10*(M10*Calculs!$J$13+N10*Calculs!$J$14+O10*Calculs!$J$15+AF10*Calculs!$J$22) -> 270150.98 | X10: =IF(S10>0,W10/S10*1000000,0) -> 12904.148 | Y10: =RL_NAV*T10*(P10*RL_Choc_Taux+Q10*RL_Choc_Spread)/10000 -> 3606071.2 | Z10: =RL_NAV*U10*(P10*RL_Choc_Taux+Q10*RL_Choc_Spread)/10000 -> 3606071.2 | AA10: =RL_NAV*T10*(1-SUMPRODUCT((Flux!$B$7:$B$926=B10)*Flux!$F$7:$F$926*EXP(-(RL_Choc_Taux+IF(Q10>0,RL_Choc_Spread,0))/10000*Flux!$D$7:$D$926))/K10) -> 3289571.1 | AB10: =RL_NAV*U10*(1-SUMPRODUCT((Flux!$B$7:$B$926=B10)*Flux!$F$7:$F$926*EXP(-(RL_Choc_Taux+IF(Q10>0,RL_Choc_Spread,0))/10000*Flux!$D$7:$D$926))/K10) -> 3289571.1 | AC10: =IF(U10>RL_Seuil_Ligne,"OUI","") | AD10: =SUMIF(Flux!$B$7:$B$926,B10,Flux!$F$7:$F$926)-K10 -> 0 | AE10: 0.84642367 | AF10: =Q10*AE10 -> 5.83183
B11: BE0390119825 | C11: UCB 4.25 03-30 | D11: UCB | E11: 47562 | F11: 4.25 | G11: 13300000 | H11: 102.4315 | I11: 161057.53 | J11: 13784447 | K11: =J11/G11*100 -> 103.64246 | L11: 149.24715 | M11: 0.60318469 | N11: 3.7299117 | O11: 0 | P11: =SUM(M11:O11) -> 4.3330964 | Q11: =IF(R11="OUI",0,P11) -> 4.3330964 | R11: NON | S11: =IF(B11=RL_ISIN_Vente,J11-RL_Montant_Vente,J11) -> 13784447 | T11: =J11/RL_NAV -> 0.0053176084 | U11: =S11/RL_NAV -> 0.0053176084 | V11: =RL_NAV*T11*(M11*Calculs!$I$13+N11*Calculs!$I$14+O11*Calculs!$I$15+AF11*Calculs!$I$22) -> 148718.34 | W11: =RL_NAV*U11*(M11*Calculs!$J$13+N11*Calculs!$J$14+O11*Calculs!$J$15+AF11*Calculs!$J$22) -> 148718.34 | X11: =IF(S11>0,W11/S11*1000000,0) -> 10788.851 | Y11: =RL_NAV*T11*(P11*RL_Choc_Taux+Q11*RL_Choc_Spread)/10000 -> 1493233.4 | Z11: =RL_NAV*U11*(P11*RL_Choc_Taux+Q11*RL_Choc_Spread)/10000 -> 1493233.4 | AA11: =RL_NAV*T11*(1-SUMPRODUCT((Flux!$B$7:$B$926=B11)*Flux!$F$7:$F$926*EXP(-(RL_Choc_Taux+IF(Q11>0,RL_Choc_Spread,0))/10000*Flux!$D$7:$D$926))/K11) -> 1411148.2 | AB11: =RL_NAV*U11*(1-SUMPRODUCT((Flux!$B$7:$B$926=B11)*Flux!$F$7:$F$926*EXP(-(RL_Choc_Taux+IF(Q11>0,RL_Choc_Spread,0))/10000*Flux!$D$7:$D$926))/K11) -> 1411148.2 | AC11: =IF(U11>RL_Seuil_Ligne,"OUI","") | AD11: =SUMIF(Flux!$B$7:$B$926,B11,Flux!$F$7:$F$926)-K11 -> 0 | AE11: 1.381918 | AF11: =Q11*AE11 -> 5.9879841
B12: BE0390128917 | C12: FLUV SY 3.875 05-34 | D12: FLUV SY | E12: 49066 | F12: 3.875 | G12: 10500000 | H12: 101.8145 | I12: 67998.29 | J12: 10758521 | K12: =J12/G12*100 -> 102.4621 | L12: 105.62007 | M12: 0.22623465 | N12: 2.1465804 | O12: 5.2305458 | P12: =SUM(M12:O12) -> 7.6033609 | Q12: =IF(R12="OUI",0,P12) -> 7.6033609 | R12: NON | S12: =IF(B12=RL_ISIN_Vente,J12-RL_Montant_Vente,J12) -> 10758521 | T12: =J12/RL_NAV -> 0.0041503007 | U12: =S12/RL_NAV -> 0.0041503007 | V12: =RL_NAV*T12*(M12*Calculs!$I$13+N12*Calculs!$I$14+O12*Calculs!$I$15+AF12*Calculs!$I$22) -> 164126.8 | W12: =RL_NAV*U12*(M12*Calculs!$J$13+N12*Calculs!$J$14+O12*Calculs!$J$15+AF12*Calculs!$J$22) -> 164126.8 | X12: =IF(S12>0,W12/S12*1000000,0) -> 15255.518 | Y12: =RL_NAV*T12*(P12*RL_Choc_Taux+Q12*RL_Choc_Spread)/10000 -> 2045022.9 | Z12: =RL_NAV*U12*(P12*RL_Choc_Taux+Q12*RL_Choc_Spread)/10000 -> 2045022.9 | AA12: =RL_NAV*T12*(1-SUMPRODUCT((Flux!$B$7:$B$926=B12)*Flux!$F$7:$F$926*EXP(-(RL_Choc_Taux+IF(Q12>0,RL_Choc_Spread,0))/10000*Flux!$D$7:$D$926))/K12) -> 1846188.7 | AB12: =RL_NAV*U12*(1-SUMPRODUCT((Flux!$B$7:$B$926=B12)*Flux!$F$7:$F$926*EXP(-(RL_Choc_Taux+IF(Q12>0,RL_Choc_Spread,0))/10000*Flux!$D$7:$D$926))/K12) -> 1846188.7 | AC12: =IF(U12>RL_Seuil_Ligne,"OUI","") | AD12: =SUMIF(Flux!$B$7:$B$926,B12,Flux!$F$7:$F$926)-K12 -> 0 | AE12: 0.97796362 | AF12: =Q12*AE12 -> 7.4358103
B13: BE0390149152 | C13: SILF NV 5.125 07-30 | D13: SILF NV | E13: 47681 | F13: 5.125 | G13: 15000000 | H13: 106.0515 | I13: 737157.53 | J13: 16644883 | K13: =J13/G13*100 -> 110.96588 | L13: 156.79601 | M13: 0.2690916 | N13: 4.079647 | O13: 0.036324153 | P13: =SUM(M13:O13) -> 4.3850628 | Q13: =IF(R13="OUI",0,P13) -> 4.3850628 | R13: NON | S13: =IF(B13=RL_ISIN_Vente,J13-RL_Montant_Vente,J13) -> 16644883 | T13: =J13/RL_NAV -> 0.0064210749 | U13: =S13/RL_NAV -> 0.0064210749 | V13: =RL_NAV*T13*(M13*Calculs!$I$13+N13*Calculs!$I$14+O13*Calculs!$I$15+AF13*Calculs!$I$22) -> 187645.79 | W13: =RL_NAV*U13*(M13*Calculs!$J$13+N13*Calculs!$J$14+O13*Calculs!$J$15+AF13*Calculs!$J$22) -> 187645.79 | X13: =IF(S13>0,W13/S13*1000000,0) -> 11273.482 | Y13: =RL_NAV*T13*(P13*RL_Choc_Taux+Q13*RL_Choc_Spread)/10000 -> 1824721.4 | Z13: =RL_NAV*U13*(P13*RL_Choc_Taux+Q13*RL_Choc_Spread)/10000 -> 1824721.4 | AA13: =RL_NAV*T13*(1-SUMPRODUCT((Flux!$B$7:$B$926=B13)*Flux!$F$7:$F$926*EXP(-(RL_Choc_Taux+IF(Q13>0,RL_Choc_Spread,0))/10000*Flux!$D$7:$D$926))/K13) -> 1718599.7 | AB13: =RL_NAV*U13*(1-SUMPRODUCT((Flux!$B$7:$B$926=B13)*Flux!$F$7:$F$926*EXP(-(RL_Choc_Taux+IF(Q13>0,RL_Choc_Spread,0))/10000*Flux!$D$7:$D$926))/K13) -> 1718599.7 | AC13: =IF(U13>RL_Seuil_Ligne,"OUI","") | AD13: =SUMIF(Flux!$B$7:$B$926,B13,Flux!$F$7:$F$926)-K13 -> 0 | AE13: 1.4518149 | AF13: =Q13*AE13 -> 6.3662995
B14: BE0390161272 | C14: BPOS SA 3.632 10-34 | D14: BPOS SA | E14: 49233 | F14: 3.632 | G14: 20000000 | H14: 100.1425 | I14: 515445.48 | J14: 20543945 | K14: =J14/G14*100 -> 102.71973 | L14: 99.390856 | M14: 0.2142604 | N14: 1.5679651 | O14: 6.0582222 | P14: =SUM(M14:O14) -> 7.8404477 | Q14: =IF(R14="OUI",0,P14) -> 7.8404477 | R14: NON | S14: =IF(B14=RL_ISIN_Vente,J14-RL_Montant_Vente,J14) -> 20543945 | T14: =J14/RL_NAV -> 0.0079252114 | U14: =S14/RL_NAV -> 0.0079252114 | V14: =RL_NAV*T14*(M14*Calculs!$I$13+N14*Calculs!$I$14+O14*Calculs!$I$15+AF14*Calculs!$I$22) -> 312078.67 | W14: =RL_NAV*U14*(M14*Calculs!$J$13+N14*Calculs!$J$14+O14*Calculs!$J$15+AF14*Calculs!$J$22) -> 312078.67 | X14: =IF(S14>0,W14/S14*1000000,0) -> 15190.786 | Y14: =RL_NAV*T14*(P14*RL_Choc_Taux+Q14*RL_Choc_Spread)/10000 -> 4026843.3 | Z14: =RL_NAV*U14*(P14*RL_Choc_Taux+Q14*RL_Choc_Spread)/10000 -> 4026843.3 | AA14: =RL_NAV*T14*(1-SUMPRODUCT((Flux!$B$7:$B$926=B14)*Flux!$F$7:$F$926*EXP(-(RL_Choc_Taux+IF(Q14>0,RL_Choc_Spread,0))/10000*Flux!$D$7:$D$926))/K14) -> 3616564 | AB14: =RL_NAV*U14*(1-SUMPRODUCT((Flux!$B$7:$B$926=B14)*Flux!$F$7:$F$926*EXP(-(RL_Choc_Taux+IF(Q14>0,RL_Choc_Spread,0))/10000*Flux!$D$7:$D$926))/K14) -> 3616564 | AC14: =IF(U14>RL_Seuil_Ligne,"OUI","") | AD14: =SUMIF(Flux!$B$7:$B$926,B14,Flux!$F$7:$F$926)-K14 -> 0 | AE14: 0.9202857 | AF14: =Q14*AE14 -> 7.2154519
B15: BE0390222884 | C15: FLUXYS 4.0 11-30 | D15: FLUXYS | E15: 47815 | F15: 4 | G15: 22000000 | H15: 101.229 | I15: 84383.56 | J15: 22354764 | K15: =J15/G15*100 -> 101.61256 | L15: 188.62035 | M15: 0.23429773 | N15: 4.2589293 | O15: 0.36657621 | P15: =SUM(M15:O15) -> 4.8598032 | Q15: =IF(R15="OUI",0,P15) -> 4.8598032 | R15: NON | S15: =IF(B15=RL_ISIN_Vente,J15-RL_Montant_Vente,J15) -> 22354764 | T15: =J15/RL_NAV -> 0.0086237684 | U15: =S15/RL_NAV -> 0.0086237684 | V15: =RL_NAV*T15*(M15*Calculs!$I$13+N15*Calculs!$I$14+O15*Calculs!$I$15+AF15*Calculs!$I$22) -> 314115.68 | W15: =RL_NAV*U15*(M15*Calculs!$J$13+N15*Calculs!$J$14+O15*Calculs!$J$15+AF15*Calculs!$J$22) -> 314115.68 | X15: =IF(S15>0,W15/S15*1000000,0) -> 14051.398 | Y15: =RL_NAV*T15*(P15*RL_Choc_Taux+Q15*RL_Choc_Spread)/10000 -> 2715993.8 | Z15: =RL_NAV*U15*(P15*RL_Choc_Taux+Q15*RL_Choc_Spread)/10000 -> 2715993.8 | AA15: =RL_NAV*T15*(1-SUMPRODUCT((Flux!$B$7:$B$926=B15)*Flux!$F$7:$F$926*EXP(-(RL_Choc_Taux+IF(Q15>0,RL_Choc_Spread,0))/10000*Flux!$D$7:$D$926))/K15) -> 2546343.3 | AB15: =RL_NAV*U15*(1-SUMPRODUCT((Flux!$B$7:$B$926=B15)*Flux!$F$7:$F$926*EXP(-(RL_Choc_Taux+IF(Q15>0,RL_Choc_Spread,0))/10000*Flux!$D$7:$D$926))/K15) -> 2546343.3 | AC15: =IF(U15>RL_Seuil_Ligne,"OUI","") | AD15: =SUMIF(Flux!$B$7:$B$926,B15,Flux!$F$7:$F$926)-K15 -> 0 | AE15: 1.7464847 | AF15: =Q15*AE15 -> 8.487572
B16: BE6327721237 | C16: VGP 1.5 04-29 | D16: VGP | E16: 47216 | F16: 1.5 | G16: 8100000 | H16: 92.0075 | I16: 28294.52 | J16: 7480902 | K16: =J16/G16*100 -> 92.356815 | L16: 171.41808 | M16: 1.542214 | N16: 2.1379392 | O16: 0 | P16: =SUM(M16:O16) -> 3.6801532 | Q16: =IF(R16="OUI",0,P16) -> 3.6801532 | R16: NON | S16: =IF(B16=RL_ISIN_Vente,J16-RL_Montant_Vente,J16) -> 7480902 | T16: =J16/RL_NAV -> 0.002885898 | U16: =S16/RL_NAV -> 0.002885898 | V16: =RL_NAV*T16*(M16*Calculs!$I$13+N16*Calculs!$I$14+O16*Calculs!$I$15+AF16*Calculs!$I$22) -> 74302.408 | W16: =RL_NAV*U16*(M16*Calculs!$J$13+N16*Calculs!$J$14+O16*Calculs!$J$15+AF16*Calculs!$J$22) -> 74302.408 | X16: =IF(S16>0,W16/S16*1000000,0) -> 9932.2793 | Y16: =RL_NAV*T16*(P16*RL_Choc_Taux+Q16*RL_Choc_Spread)/10000 -> 688271.64 | Z16: =RL_NAV*U16*(P16*RL_Choc_Taux+Q16*RL_Choc_Spread)/10000 -> 688271.64 | AA16: =RL_NAV*T16*(1-SUMPRODUCT((Flux!$B$7:$B$926=B16)*Flux!$F$7:$F$926*EXP(-(RL_Choc_Taux+IF(Q16>0,RL_Choc_Spread,0))/10000*Flux!$D$7:$D$926))/K16) -> 657103.18 | AB16: =RL_NAV*U16*(1-SUMPRODUCT((Flux!$B$7:$B$926=B16)*Flux!$F$7:$F$926*EXP(-(RL_Choc_Taux+IF(Q16>0,RL_Choc_Spread,0))/10000*Flux!$D$7:$D$926))/K16) -> 657103.18 | AC16: =IF(U16>RL_Seuil_Ligne,"OUI","") | AD16: =SUMIF(Flux!$B$7:$B$926,B16,Flux!$F$7:$F$926)-K16 -> 0 | AE16: 1.5872045 | AF16: =Q16*AE16 -> 5.8411555
B17: BE6331562817 | C17: ALIA FI 0.875 11-28 | D17: ALIA FI | E17: 47065 | F17: 0.875 | G17: 12000000 | H17: 92.797 | I17: 67890.41 | J17: 11203530 | K17: =J17/G17*100 -> 93.362753 | L17: 113.2716 | M17: 1.8212434 | N17: 1.483515 | O17: 0 | P17: =SUM(M17:O17) -> 3.3047584 | Q17: =IF(R17="OUI",0,P17) -> 3.3047584 | R17: NON | S17: =IF(B17=RL_ISIN_Vente,J17-RL_Montant_Vente,J17) -> 11203530 | T17: =J17/RL_NAV -> 0.0043219715 | U17: =S17/RL_NAV -> 0.0043219715 | V17: =RL_NAV*T17*(M17*Calculs!$I$13+N17*Calculs!$I$14+O17*Calculs!$I$15+AF17*Calculs!$I$22) -> 77704.781 | W17: =RL_NAV*U17*(M17*Calculs!$J$13+N17*Calculs!$J$14+O17*Calculs!$J$15+AF17*Calculs!$J$22) -> 77704.781 | X17: =IF(S17>0,W17/S17*1000000,0) -> 6935.7406 | Y17: =RL_NAV*T17*(P17*RL_Choc_Taux+Q17*RL_Choc_Spread)/10000 -> 925624.04 | Z17: =RL_NAV*U17*(P17*RL_Choc_Taux+Q17*RL_Choc_Spread)/10000 -> 925624.04 | AA17: =RL_NAV*T17*(1-SUMPRODUCT((Flux!$B$7:$B$926=B17)*Flux!$F$7:$F$926*EXP(-(RL_Choc_Taux+IF(Q17>0,RL_Choc_Spread,0))/10000*Flux!$D$7:$D$926))/K17) -> 888006.15 | AB17: =RL_NAV*U17*(1-SUMPRODUCT((Flux!$B$7:$B$926=B17)*Flux!$F$7:$F$926*EXP(-(RL_Choc_Taux+IF(Q17>0,RL_Choc_Spread,0))/10000*Flux!$D$7:$D$926))/K17) -> 888006.15 | AC17: =IF(U17>RL_Seuil_Ligne,"OUI","") | AD17: =SUMIF(Flux!$B$7:$B$926,B17,Flux!$F$7:$F$926)-K17 -> 0 | AE17: 1.0488111 | AF17: =Q17*AE17 -> 3.4660672
B18: BE6332786449 | C18: VGP 1.625 01-27 | D18: VGP | E18: 46404 | F18: 1.625 | G18: 4800000 | H18: 98.0555 | I18: 35473.97 | J18: 4742138 | K18: =J18/G18*100 -> 98.794541 | L18: 103.12627 | M18: 1.5334446 | N18: 0 | O18: 0 | P18: =SUM(M18:O18) -> 1.5334446 | Q18: =IF(R18="OUI",0,P18) -> 1.5334446 | R18: NON | S18: =IF(B18=RL_ISIN_Vente,J18-RL_Montant_Vente,J18) -> 4742138 | T18: =J18/RL_NAV -> 0.0018293685 | U18: =S18/RL_NAV -> 0.0018293685 | V18: =RL_NAV*T18*(M18*Calculs!$I$13+N18*Calculs!$I$14+O18*Calculs!$I$15+AF18*Calculs!$I$22) -> 14313.957 | W18: =RL_NAV*U18*(M18*Calculs!$J$13+N18*Calculs!$J$14+O18*Calculs!$J$15+AF18*Calculs!$J$22) -> 14313.957 | X18: =IF(S18>0,W18/S18*1000000,0) -> 3018.4607 | Y18: =RL_NAV*T18*(P18*RL_Choc_Taux+Q18*RL_Choc_Spread)/10000 -> 181795.15 | Z18: =RL_NAV*U18*(P18*RL_Choc_Taux+Q18*RL_Choc_Spread)/10000 -> 181795.15 | AA18: =RL_NAV*T18*(1-SUMPRODUCT((Flux!$B$7:$B$926=B18)*Flux!$F$7:$F$926*EXP(-(RL_Choc_Taux+IF(Q18>0,RL_Choc_Spread,0))/10000*Flux!$D$7:$D$926))/K18) -> 178331.73 | AB18: =RL_NAV*U18*(1-SUMPRODUCT((Flux!$B$7:$B$926=B18)*Flux!$F$7:$F$926*EXP(-(RL_Choc_Taux+IF(Q18>0,RL_Choc_Spread,0))/10000*Flux!$D$7:$D$926))/K18) -> 178331.73 | AC18: =IF(U18>RL_Seuil_Ligne,"OUI","") | AD18: =SUMIF(Flux!$B$7:$B$926,B18,Flux!$F$7:$F$926)-K18 -> 0 | AE18: 0.95487289 | AF18: =Q18*AE18 -> 1.4642447
... B173: XS3100767915 | C173: SES 4.125 06-30 | D173: SES | E173: 47658 | F173: 4.125 | G173: 15900000 | H173: 100.92 | I173: 14375.34 | J173: 16060655 | K173: =J173/G173*100 -> 101.01041 | L173: 170.02987 | M173: 0.25930525 | N173: 4.3432562 | O173: 0 | P173: =SUM(M173:O173) -> 4.6025615 | Q173: =IF(R173="OUI",0,P173) -> 4.6025615 | R173: NON | S173: =IF(B173=RL_ISIN_Vente,J173-RL_Montant_Vente,J173) -> 16060655 | T173: =J173/RL_NAV -> 0.0061956984 | U173: =S173/RL_NAV -> 0.0061956984 | V173: =RL_NAV*T173*(M173*Calculs!$I$13+N173*Calculs!$I$14+O173*Calculs!$I$15+AF173*Calculs!$I$22) -> 200066.67 | W173: =RL_NAV*U173*(M173*Calculs!$J$13+N173*Calculs!$J$14+O173*Calculs!$J$15+AF173*Calculs!$J$22) -> 200066.67 | X173: =IF(S173>0,W173/S173*1000000,0) -> 12456.943 | Y173: =RL_NAV*T173*(P173*RL_Choc_Taux+Q173*RL_Choc_Spread)/10000 -> 1848003.8 | Z173: =RL_NAV*U173*(P173*RL_Choc_Taux+Q173*RL_Choc_Spread)/10000 -> 1848003.8 | AA173: =RL_NAV*T173*(1-SUMPRODUCT((Flux!$B$7:$B$926=B173)*Flux!$F$7:$F$926*EXP(-(RL_Choc_Taux+IF(Q173>0,RL_Choc_Spread,0))/10000*Flux!$D$7:$D$926))/K173) -> 1741025.3 | AB173: =RL_NAV*U173*(1-SUMPRODUCT((Flux!$B$7:$B$926=B173)*Flux!$F$7:$F$926*EXP(-(RL_Choc_Taux+IF(Q173>0,RL_Choc_Spread,0))/10000*Flux!$D$7:$D$926))/K173) -> 1741025.3 | AC173: =IF(U173>RL_Seuil_Ligne,"OUI","") | AD173: =SUMIF(Flux!$B$7:$B$926,B173,Flux!$F$7:$F$926)-K173 -> 0 | AE173: 1.5743507 | AF173: =Q173*AE173 -> 7.2460458
B174: LIQUIDITES | C174: Liquidités issues des ventes simulées | J174: 0 | M174: 0 | N174: 0 | O174: 0 | P174: 0 | Q174: 0 | S174: =RL_Montant_Vente -> 20000000 | T174: =J174/RL_NAV -> 0 | U174: =S174/RL_NAV -> 0.0077153743 | V174: 0 | W174: 0 | Y174: 0 | Z174: 0 | AA174: 0 | AB174: 0 | AE174: 0 | AF174: 0
C175: Total | J175: =SUM(J7:J174) -> 2.5922268e+09 | S175: =SUM(S7:S174) -> 2.5922268e+09 | T175: =SUM(T7:T174) -> 1 | U175: =SUM(U7:U174) -> 1 | V175: =SUM(V7:V174) -> 29274800 | W175: =SUM(W7:W174) -> 28675584 | Y175: =SUM(Y7:Y174) -> 3.0556203e+08 | Z175: =SUM(Z7:Z174) -> 3.0176083e+08 | AA175: =SUM(AA7:AA174) -> 2.831167e+08 | AB175: =SUM(AB7:AB174) -> 2.7971774e+08

Sheet Calculs
B2: Distribution des pertes historiques
B3: Perte du jour = valeur x (sensibilités aux taux x variations de taux + sensibilité spread x variation du spread). Pertes positives. Poids de queue : part de chaque scénario dans l'ES.
B6: Date | C6: Perte initiale (EUR) | D6: Perte après vente (EUR) | E6: Poids de queue initial | F6: Poids de queue après | H6: Grandeur | I6: Initial | J6: Après vente
B7: =Historique!B7 -> 44406 | C7: =RL_NAV*($I$10*Historique!D7+$I$11*Historique!E7+$I$12*Historique!F7+$I$21*Historique!G7) -> -1505254.7 | D7: =RL_NAV*($J$10*Historique!D7+$J$11*Historique!E7+$J$12*Historique!F7+$J$21*Historique!G7) -> -1462936.1 | E7: =IF(C7>$I$9,1,IF(C7=$I$9,($I$8-$I$18)/$I$19,0))/$I$8 -> 0 | F7: =IF(D7>$J$9,1,IF(D7=$J$9,($J$8-$J$18)/$J$19,0))/$J$8 -> 0 | H7: Nombre de scénarios | I7: =COUNT(Historique!$D$7:$D$1006) -> 1000 | J7: =COUNT(Historique!$D$7:$D$1006) -> 1000
B8: =Historique!B8 -> 44407 | C8: =RL_NAV*($I$10*Historique!D8+$I$11*Historique!E8+$I$12*Historique!F8+$I$21*Historique!G8) -> -2239750.6 | D8: =RL_NAV*($J$10*Historique!D8+$J$11*Historique!E8+$J$12*Historique!F8+$J$21*Historique!G8) -> -2187073.4 | E8: =IF(C8>$I$9,1,IF(C8=$I$9,($I$8-$I$18)/$I$19,0))/$I$8 -> 0 | F8: =IF(D8>$J$9,1,IF(D8=$J$9,($J$8-$J$18)/$J$19,0))/$J$8 -> 0 | H8: Masse de queue (journées) | I8: =ROUND(I7*(1-RL_Confiance),8) -> 10 | J8: =ROUND(J7*(1-RL_Confiance),8) -> 10
B9: =Historique!B9 -> 44410 | C9: =RL_NAV*($I$10*Historique!D9+$I$11*Historique!E9+$I$12*Historique!F9+$I$21*Historique!G9) -> -5085084.9 | D9: =RL_NAV*($J$10*Historique!D9+$J$11*Historique!E9+$J$12*Historique!F9+$J$21*Historique!G9) -> -4972838.6 | E9: =IF(C9>$I$9,1,IF(C9=$I$9,($I$8-$I$18)/$I$19,0))/$I$8 -> 0 | F9: =IF(D9>$J$9,1,IF(D9=$J$9,($J$8-$J$18)/$J$19,0))/$J$8 -> 0 | H9: Seuil de queue (EUR) | I9: =LARGE(C7:C1006,ROUNDUP(I8,0)) -> 22404741 | J9: =LARGE(D7:D1006,ROUNDUP(J8,0)) -> 21959031
B10: =Historique!B10 -> 44411 | C10: =RL_NAV*($I$10*Historique!D10+$I$11*Historique!E10+$I$12*Historique!F10+$I$21*Historique!G10) -> -2645283.3 | D10: =RL_NAV*($J$10*Historique!D10+$J$11*Historique!E10+$J$12*Historique!F10+$J$21*Historique!G10) -> -2605791 | E10: =IF(C10>$I$9,1,IF(C10=$I$9,($I$8-$I$18)/$I$19,0))/$I$8 -> 0 | F10: =IF(D10>$J$9,1,IF(D10=$J$9,($J$8-$J$18)/$J$19,0))/$J$8 -> 0 | H10: Sensibilité 2 ans du portefeuille | I10: =SUMPRODUCT(Positions!$T$7:$T$174,Positions!$M$7:$M$174) -> 0.76143393 | J10: =SUMPRODUCT(Positions!$U$7:$U$174,Positions!$M$7:$M$174) -> 0.75925113
B11: =Historique!B11 -> 44412 | C11: =RL_NAV*($I$10*Historique!D11+$I$11*Historique!E11+$I$12*Historique!F11+$I$21*Historique!G11) -> -1607932.6 | D11: =RL_NAV*($J$10*Historique!D11+$J$11*Historique!E11+$J$12*Historique!F11+$J$21*Historique!G11) -> -1582275.9 | E11: =IF(C11>$I$9,1,IF(C11=$I$9,($I$8-$I$18)/$I$19,0))/$I$8 -> 0 | F11: =IF(D11>$J$9,1,IF(D11=$J$9,($J$8-$J$18)/$J$19,0))/$J$8 -> 0 | H11: Sensibilité 5 ans du portefeuille | I11: =SUMPRODUCT(Positions!$T$7:$T$174,Positions!$N$7:$N$174) -> 2.5048707 | J11: =SUMPRODUCT(Positions!$U$7:$U$174,Positions!$N$7:$N$174) -> 2.4984385
B12: =Historique!B12 -> 44413 | C12: =RL_NAV*($I$10*Historique!D12+$I$11*Historique!E12+$I$12*Historique!F12+$I$21*Historique!G12) -> 1964579.3 | D12: =RL_NAV*($J$10*Historique!D12+$J$11*Historique!E12+$J$12*Historique!F12+$J$21*Historique!G12) -> 1914662.9 | E12: =IF(C12>$I$9,1,IF(C12=$I$9,($I$8-$I$18)/$I$19,0))/$I$8 -> 0 | F12: =IF(D12>$J$9,1,IF(D12=$J$9,($J$8-$J$18)/$J$19,0))/$J$8 -> 0 | H12: Sensibilité 10 ans du portefeuille | I12: =SUMPRODUCT(Positions!$T$7:$T$174,Positions!$O$7:$O$174) -> 1.6330994 | J12: =SUMPRODUCT(Positions!$U$7:$U$174,Positions!$O$7:$O$174) -> 1.583059
B13: =Historique!B13 -> 44414 | C13: =RL_NAV*($I$10*Historique!D13+$I$11*Historique!E13+$I$12*Historique!F13+$I$21*Historique!G13) -> 4838953 | D13: =RL_NAV*($J$10*Historique!D13+$J$11*Historique!E13+$J$12*Historique!F13+$J$21*Historique!G13) -> 4773696.7 | E13: =IF(C13>$I$9,1,IF(C13=$I$9,($I$8-$I$18)/$I$19,0))/$I$8 -> 0 | F13: =IF(D13>$J$9,1,IF(D13=$J$9,($J$8-$J$18)/$J$19,0))/$J$8 -> 0 | H13: Variation moyenne en queue, 2 ans | I13: =SUMPRODUCT(Historique!$D$7:$D$1006,E7:E1006) -> 0.00091805825 | J13: =SUMPRODUCT(Historique!$D$7:$D$1006,F7:F1006) -> 0.00091805825
B14: =Historique!B14 -> 44417 | C14: =RL_NAV*($I$10*Historique!D14+$I$11*Historique!E14+$I$12*Historique!F14+$I$21*Historique!G14) -> -626677.9 | D14: =RL_NAV*($J$10*Historique!D14+$J$11*Historique!E14+$J$12*Historique!F14+$J$21*Historique!G14) -> -611511.18 | E14: =IF(C14>$I$9,1,IF(C14=$I$9,($I$8-$I$18)/$I$19,0))/$I$8 -> 0 | F14: =IF(D14>$J$9,1,IF(D14=$J$9,($J$8-$J$18)/$J$19,0))/$J$8 -> 0 | H14: Variation moyenne en queue, 5 ans | I14: =SUMPRODUCT(Historique!$E$7:$E$1006,E7:E1006) -> 0.00097812228 | J14: =SUMPRODUCT(Historique!$E$7:$E$1006,F7:F1006) -> 0.00097812228
B15: =Historique!B15 -> 44418 | C15: =RL_NAV*($I$10*Historique!D15+$I$11*Historique!E15+$I$12*Historique!F15+$I$21*Historique!G15) -> -1914549.5 | D15: =RL_NAV*($J$10*Historique!D15+$J$11*Historique!E15+$J$12*Historique!F15+$J$21*Historique!G15) -> -1866784.1 | E15: =IF(C15>$I$9,1,IF(C15=$I$9,($I$8-$I$18)/$I$19,0))/$I$8 -> 0 | F15: =IF(D15>$J$9,1,IF(D15=$J$9,($J$8-$J$18)/$J$19,0))/$J$8 -> 0 | H15: Variation moyenne en queue, 10 ans | I15: =SUMPRODUCT(Historique!$F$7:$F$1006,E7:E1006) -> 0.00091172349 | J15: =SUMPRODUCT(Historique!$F$7:$F$1006,F7:F1006) -> 0.00091172349
B16: =Historique!B16 -> 44419 | C16: =RL_NAV*($I$10*Historique!D16+$I$11*Historique!E16+$I$12*Historique!F16+$I$21*Historique!G16) -> 2471469.7 | D16: =RL_NAV*($J$10*Historique!D16+$J$11*Historique!E16+$J$12*Historique!F16+$J$21*Historique!G16) -> 2440857.4 | E16: =IF(C16>$I$9,1,IF(C16=$I$9,($I$8-$I$18)/$I$19,0))/$I$8 -> 0 | F16: =IF(D16>$J$9,1,IF(D16=$J$9,($J$8-$J$18)/$J$19,0))/$J$8 -> 0 | H16: VaR (EUR) | I16: =LARGE(C7:C1006,I7-ROUNDUP(ROUND(RL_Confiance*I7,9),0)+1) -> 20982292 | J16: =LARGE(D7:D1006,J7-ROUNDUP(ROUND(RL_Confiance*J7,9),0)+1) -> 20535074
B17: =Historique!B17 -> 44420 | C17: =RL_NAV*($I$10*Historique!D17+$I$11*Historique!E17+$I$12*Historique!F17+$I$21*Historique!G17) -> 380475.26 | D17: =RL_NAV*($J$10*Historique!D17+$J$11*Historique!E17+$J$12*Historique!F17+$J$21*Historique!G17) -> 375341.1 | E17: =IF(C17>$I$9,1,IF(C17=$I$9,($I$8-$I$18)/$I$19,0))/$I$8 -> 0 | F17: =IF(D17>$J$9,1,IF(D17=$J$9,($J$8-$J$18)/$J$19,0))/$J$8 -> 0 | H17: Expected Shortfall (EUR) | I17: =SUMPRODUCT(C7:C1006,E7:E1006) -> 29274800 | J17: =SUMPRODUCT(D7:D1006,F7:F1006) -> 28675584
B18: =Historique!B18 -> 44421 | C18: =RL_NAV*($I$10*Historique!D18+$I$11*Historique!E18+$I$12*Historique!F18+$I$21*Historique!G18) -> 1338335.9 | D18: =RL_NAV*($J$10*Historique!D18+$J$11*Historique!E18+$J$12*Historique!F18+$J$21*Historique!G18) -> 1308184.9 | E18: =IF(C18>$I$9,1,IF(C18=$I$9,($I$8-$I$18)/$I$19,0))/$I$8 -> 0 | F18: =IF(D18>$J$9,1,IF(D18=$J$9,($J$8-$J$18)/$J$19,0))/$J$8 -> 0 | H18: Scénarios au-delà du seuil | I18: =SUMPRODUCT(--(C7:C1006>I9)) -> 9 | J18: =SUMPRODUCT(--(D7:D1006>J9)) -> 9
B19: =Historique!B19 -> 44424 | C19: =RL_NAV*($I$10*Historique!D19+$I$11*Historique!E19+$I$12*Historique!F19+$I$21*Historique!G19) -> -2618505.5 | D19: =RL_NAV*($J$10*Historique!D19+$J$11*Historique!E19+$J$12*Historique!F19+$J$21*Historique!G19) -> -2579109.2 | E19: =IF(C19>$I$9,1,IF(C19=$I$9,($I$8-$I$18)/$I$19,0))/$I$8 -> 0 | F19: =IF(D19>$J$9,1,IF(D19=$J$9,($J$8-$J$18)/$J$19,0))/$J$8 -> 0 | H19: Scénarios égaux au seuil | I19: =SUMPRODUCT(--(C7:C1006=I9)) -> 1 | J19: =SUMPRODUCT(--(D7:D1006=J9)) -> 1
B20: =Historique!B20 -> 44425 | C20: =RL_NAV*($I$10*Historique!D20+$I$11*Historique!E20+$I$12*Historique!F20+$I$21*Historique!G20) -> 3136364.1 | D20: =RL_NAV*($J$10*Historique!D20+$J$11*Historique!E20+$J$12*Historique!F20+$J$21*Historique!G20) -> 3070080.2 | E20: =IF(C20>$I$9,1,IF(C20=$I$9,($I$8-$I$18)/$I$19,0))/$I$8 -> 0 | F20: =IF(D20>$J$9,1,IF(D20=$J$9,($J$8-$J$18)/$J$19,0))/$J$8 -> 0 | H20: Somme des poids de queue | I20: =SUM(E7:E1006) -> 1 | J20: =SUM(F7:F1006) -> 1
B21: =Historique!B21 -> 44426 | C21: =RL_NAV*($I$10*Historique!D21+$I$11*Historique!E21+$I$12*Historique!F21+$I$21*Historique!G21) -> -877446.95 | D21: =RL_NAV*($J$10*Historique!D21+$J$11*Historique!E21+$J$12*Historique!F21+$J$21*Historique!G21) -> -864774.06 | E21: =IF(C21>$I$9,1,IF(C21=$I$9,($I$8-$I$18)/$I$19,0))/$I$8 -> 0 | F21: =IF(D21>$J$9,1,IF(D21=$J$9,($J$8-$J$18)/$J$19,0))/$J$8 -> 0 | H21: Sensibilité spread du portefeuille | I21: =SUMPRODUCT(Positions!$T$7:$T$174,Positions!$AF$7:$AF$174) -> 6.0502331 | J21: =SUMPRODUCT(Positions!$U$7:$U$174,Positions!$AF$7:$AF$174) -> 5.8891056
B22: =Historique!B22 -> 44427 | C22: =RL_NAV*($I$10*Historique!D22+$I$11*Historique!E22+$I$12*Historique!F22+$I$21*Historique!G22) -> 1493426.3 | D22: =RL_NAV*($J$10*Historique!D22+$J$11*Historique!E22+$J$12*Historique!F22+$J$21*Historique!G22) -> 1456989.9 | E22: =IF(C22>$I$9,1,IF(C22=$I$9,($I$8-$I$18)/$I$19,0))/$I$8 -> 0 | F22: =IF(D22>$J$9,1,IF(D22=$J$9,($J$8-$J$18)/$J$19,0))/$J$8 -> 0 | H22: Variation moyenne en queue, spread | I22: =SUMPRODUCT(Historique!$G$7:$G$1006,E7:E1006) -> 0.0011 | J22: =SUMPRODUCT(Historique!$G$7:$G$1006,F7:F1006) -> 0.0011
B23: =Historique!B23 -> 44428 | C23: =RL_NAV*($I$10*Historique!D23+$I$11*Historique!E23+$I$12*Historique!F23+$I$21*Historique!G23) -> -2337635.8 | D23: =RL_NAV*($J$10*Historique!D23+$J$11*Historique!E23+$J$12*Historique!F23+$J$21*Historique!G23) -> -2284751.1 | E23: =IF(C23>$I$9,1,IF(C23=$I$9,($I$8-$I$18)/$I$19,0))/$I$8 -> 0 | F23: =IF(D23>$J$9,1,IF(D23=$J$9,($J$8-$J$18)/$J$19,0))/$J$8 -> 0
B24: =Historique!B24 -> 44431 | C24: =RL_NAV*($I$10*Historique!D24+$I$11*Historique!E24+$I$12*Historique!F24+$I$21*Historique!G24) -> -688659.38 | D24: =RL_NAV*($J$10*Historique!D24+$J$11*Historique!E24+$J$12*Historique!F24+$J$21*Historique!G24) -> -666185.07 | E24: =IF(C24>$I$9,1,IF(C24=$I$9,($I$8-$I$18)/$I$19,0))/$I$8 -> 0 | F24: =IF(D24>$J$9,1,IF(D24=$J$9,($J$8-$J$18)/$J$19,0))/$J$8 -> 0
B25: =Historique!B25 -> 44432 | C25: =RL_NAV*($I$10*Historique!D25+$I$11*Historique!E25+$I$12*Historique!F25+$I$21*Historique!G25) -> 3743207.3 | D25: =RL_NAV*($J$10*Historique!D25+$J$11*Historique!E25+$J$12*Historique!F25+$J$21*Historique!G25) -> 3654341.5 | E25: =IF(C25>$I$9,1,IF(C25=$I$9,($I$8-$I$18)/$I$19,0))/$I$8 -> 0 | F25: =IF(D25>$J$9,1,IF(D25=$J$9,($J$8-$J$18)/$J$19,0))/$J$8 -> 0
B26: =Historique!B26 -> 44433 | C26: =RL_NAV*($I$10*Historique!D26+$I$11*Historique!E26+$I$12*Historique!F26+$I$21*Historique!G26) -> 1879547 | D26: =RL_NAV*($J$10*Historique!D26+$J$11*Historique!E26+$J$12*Historique!F26+$J$21*Historique!G26) -> 1860704.7 | E26: =IF(C26>$I$9,1,IF(C26=$I$9,($I$8-$I$18)/$I$19,0))/$I$8 -> 0 | F26: =IF(D26>$J$9,1,IF(D26=$J$9,($J$8-$J$18)/$J$19,0))/$J$8 -> 0
B27: =Historique!B27 -> 44434 | C27: =RL_NAV*($I$10*Historique!D27+$I$11*Historique!E27+$I$12*Historique!F27+$I$21*Historique!G27) -> -348992.67 | D27: =RL_NAV*($J$10*Historique!D27+$J$11*Historique!E27+$J$12*Historique!F27+$J$21*Historique!G27) -> -306642.84 | E27: =IF(C27>$I$9,1,IF(C27=$I$9,($I$8-$I$18)/$I$19,0))/$I$8 -> 0 | F27: =IF(D27>$J$9,1,IF(D27=$J$9,($J$8-$J$18)/$J$19,0))/$J$8 -> 0
B28: =Historique!B28 -> 44435 | C28: =RL_NAV*($I$10*Historique!D28+$I$11*Historique!E28+$I$12*Historique!F28+$I$21*Historique!G28) -> 3357042.8 | D28: =RL_NAV*($J$10*Historique!D28+$J$11*Historique!E28+$J$12*Historique!F28+$J$21*Historique!G28) -> 3270915.7 | E28: =IF(C28>$I$9,1,IF(C28=$I$9,($I$8-$I$18)/$I$19,0))/$I$8 -> 0 | F28: =IF(D28>$J$9,1,IF(D28=$J$9,($J$8-$J$18)/$J$19,0))/$J$8 -> 0
B29: =Historique!B29 -> 44438 | C29: =RL_NAV*($I$10*Historique!D29+$I$11*Historique!E29+$I$12*Historique!F29+$I$21*Historique!G29) -> -1721563.7 | D29: =RL_NAV*($J$10*Historique!D29+$J$11*Historique!E29+$J$12*Historique!F29+$J$21*Historique!G29) -> -1693289 | E29: =IF(C29>$I$9,1,IF(C29=$I$9,($I$8-$I$18)/$I$19,0))/$I$8 -> 0 | F29: =IF(D29>$J$9,1,IF(D29=$J$9,($J$8-$J$18)/$J$19,0))/$J$8 -> 0
B30: =Historique!B30 -> 44439 | C30: =RL_NAV*($I$10*Historique!D30+$I$11*Historique!E30+$I$12*Historique!F30+$I$21*Historique!G30) -> 4271822.3 | D30: =RL_NAV*($J$10*Historique!D30+$J$11*Historique!E30+$J$12*Historique!F30+$J$21*Historique!G30) -> 4195731.6 | E30: =IF(C30>$I$9,1,IF(C30=$I$9,($I$8-$I$18)/$I$19,0))/$I$8 -> 0 | F30: =IF(D30>$J$9,1,IF(D30=$J$9,($J$8-$J$18)/$J$19,0))/$J$8 -> 0
B31: =Historique!B31 -> 44440 | C31: =RL_NAV*($I$10*Historique!D31+$I$11*Historique!E31+$I$12*Historique!F31+$I$21*Historique!G31) -> -501544.78 | D31: =RL_NAV*($J$10*Historique!D31+$J$11*Historique!E31+$J$12*Historique!F31+$J$21*Historique!G31) -> -484613.18 | E31: =IF(C31>$I$9,1,IF(C31=$I$9,($I$8-$I$18)/$I$19,0))/$I$8 -> 0 | F31: =IF(D31>$J$9,1,IF(D31=$J$9,($J$8-$J$18)/$J$19,0))/$J$8 -> 0
B32: =Historique!B32 -> 44441 | C32: =RL_NAV*($I$10*Historique!D32+$I$11*Historique!E32+$I$12*Historique!F32+$I$21*Historique!G32) -> -946065.98 | D32: =RL_NAV*($J$10*Historique!D32+$J$11*Historique!E32+$J$12*Historique!F32+$J$21*Historique!G32) -> -933294.39 | E32: =IF(C32>$I$9,1,IF(C32=$I$9,($I$8-$I$18)/$I$19,0))/$I$8 -> 0 | F32: =IF(D32>$J$9,1,IF(D32=$J$9,($J$8-$J$18)/$J$19,0))/$J$8 -> 0
B33: =Historique!B33 -> 44442 | C33: =RL_NAV*($I$10*Historique!D33+$I$11*Historique!E33+$I$12*Historique!F33+$I$21*Historique!G33) -> 2811830.3 | D33: =RL_NAV*($J$10*Historique!D33+$J$11*Historique!E33+$J$12*Historique!F33+$J$21*Historique!G33) -> 2765013.1 | E33: =IF(C33>$I$9,1,IF(C33=$I$9,($I$8-$I$18)/$I$19,0))/$I$8 -> 0 | F33: =IF(D33>$J$9,1,IF(D33=$J$9,($J$8-$J$18)/$J$19,0))/$J$8 -> 0
B34: =Historique!B34 -> 44445 | C34: =RL_NAV*($I$10*Historique!D34+$I$11*Historique!E34+$I$12*Historique!F34+$I$21*Historique!G34) -> -228135.06 | D34: =RL_NAV*($J$10*Historique!D34+$J$11*Historique!E34+$J$12*Historique!F34+$J$21*Historique!G34) -> -218937.66 | E34: =IF(C34>$I$9,1,IF(C34=$I$9,($I$8-$I$18)/$I$19,0))/$I$8 -> 0 | F34: =IF(D34>$J$9,1,IF(D34=$J$9,($J$8-$J$18)/$J$19,0))/$J$8 -> 0
... B1006: =Historique!B1006 -> 45838 | C1006: =RL_NAV*($I$10*Historique!D1006+$I$11*Historique!E1006+$I$12*Historique!F1006+$I$21*Historique!G1006) -> -1931812.9 | D1006: =RL_NAV*($J$10*Historique!D1006+$J$11*Historique!E1006+$J$12*Historique!F1006+$J$21*Historique!G1006) -> -1880093.7 | E1006: =IF(C1006>$I$9,1,IF(C1006=$I$9,($I$8-$I$18)/$I$19,0))/$I$8 -> 0 | F1006: =IF(D1006>$J$9,1,IF(D1006=$J$9,($J$8-$J$18)/$J$19,0))/$J$8 -> 0

Sheet Historique
B2: Historique des variations de taux et de spread
B3: Courbe AAA de la BCE, zéro-coupon continu ; spread crédit Bundesbank si raccordé. Variation entre deux dates d'observation communes successives, sans remplissage. Décimales.
B6: Date | C6: Date précédente | D6: Variation 2 ans | E6: Variation 5 ans | F6: Variation 10 ans | G6: Variation du spread
B7: 44406 | C7: 44405 | D7: -6.5265934e-07 | E7: 1.3824484e-05 | F7: -5.993778e-06 | G7: -0.0001
B8: 44407 | C8: 44406 | D8: -3.2183551e-05 | E8: -4.3331189e-05 | F8: -7.7128026e-05 | G8: -0.0001
B9: 44410 | C9: 44407 | D9: -3.8996049e-05 | E9: -0.00015828009 | F9: -0.00019928732 | G9: -0.0002
B10: 44411 | C10: 44410 | D10: -9.998031e-05 | E10: -0.00019793937 | F10: -0.00027464747 | G10: 0
B11: 44412 | C11: 44411 | D11: -4.5704726e-05 | E11: -0.0001157897 | F11: -0.00018091412 | G11: 0
B12: 44413 | C12: 44412 | D12: -4.4193826e-05 | E12: 3.5191762e-05 | F12: 6.0222792e-05 | G12: 0.0001
B13: 44414 | C13: 44413 | D13: 0.00023757504 | E13: 0.00038396386 | F13: 0.00044335279 | G13: 0
B14: 44417 | C14: 44414 | D14: 2.8301329e-05 | E14: -3.0649933e-05 | F14: -0.0001142173 | G14: 0
B15: 44418 | C15: 44417 | D15: 8.2606395e-06 | E15: -2.7775954e-05 | F15: -4.3025396e-05 | G15: -0.0001
B16: 44419 | C16: 44418 | D16: 8.4141552e-05 | E16: 0.00022219999 | F16: 0.000203763 | G16: 0
B17: 44420 | C17: 44419 | D17: -6.55751e-07 | E17: 3.5987685e-05 | F17: 3.4982724e-05 | G17: 0
B18: 44421 | C18: 44420 | D18: 4.2938602e-05 | E18: 1.2150241e-05 | F18: -9.2991829e-05 | G18: 0.0001
... B1006: 45838 | C1006: 45835 | D1006: -6.372752e-06 | E1006: -4.58677e-06 | F1006: -7.5848391e-05 | G1006: -0.0001

Sheet Flux
B2: Flux du modèle
B3: Coupons annuels et remboursement à l'échéance, en % du nominal. Valeur actuelle après calibration du spread ; la somme par titre égale le prix dirty.
B6: ISIN | C6: Date du flux | D6: Temps (années) | E6: Montant (% nominal) | F6: Valeur actuelle (% nominal)
B7: AT0000A3KDQ3 | C7: 46113 | D7: 0.75290897 | E7: 4.25 | F7: 4.1387322
B8: AT0000A3KDQ3 | C8: 46478 | D8: 1.7522245 | E8: 4.25 | F8: 3.9955356
B9: AT0000A3KDQ3 | C9: 46844 | D9: 2.7542779 | E9: 4.25 | F9: 3.8486222
B10: AT0000A3KDQ3 | C10: 47209 | D10: 3.7535934 | E10: 4.25 | F10: 3.6981493
B11: AT0000A3KDQ3 | C11: 47574 | D11: 4.752909 | E11: 4.25 | F11: 3.5462081
B12: AT0000A3KDQ3 | C12: 47939 | D12: 5.7522245 | E12: 104.25 | F12: 83.236486
B13: AT000B122080 | C13: 46104 | D13: 0.72826831 | E13: 100.875 | F13: 99.050623
B14: AT000B122296 | C14: 45995 | D14: 0.42984257 | E14: 5.5 | F14: 5.4021485
B15: AT000B122296 | C15: 46360 | D15: 1.4291581 | E15: 5.5 | F15: 5.181335
B16: AT000B122296 | C16: 46725 | D16: 2.4284736 | E16: 5.5 | F16: 4.9641885
B17: AT000B122296 | C17: 47091 | D17: 3.430527 | E17: 5.5 | F17: 4.7416824
B18: AT000B122296 | C18: 47456 | D18: 4.4298426 | E18: 5.5 | F18: 4.5203333
... B926: XS3100767915 | C926: 47658 | D926: 4.9828884 | E926: 104.125 | F926: 85.929521

Sheet Backtest
B2: Contrôle glissant de la VaR (portefeuille initial)
B3: Chaque VaR n'utilise que les 250 pertes strictement antérieures. P&L modélisé à positions constantes : ce test vérifie le modèle de taux, pas les pertes réalisées par le fonds.
B6: Date | C6: Perte (EUR) | D6: VaR prévue (EUR) | E6: Exception | G6: Synthèse | H6: Valeur
B7: =Calculs!B757 -> 45477 | C7: =Calculs!C757 -> -1824504.5 | D7: =LARGE(Calculs!C507:C756,250-ROUNDUP(ROUND(RL_Confiance*250,9),0)+1) -> 13902951 | E7: =IF(C7>D7,1,0) -> 0 | G7: Prévisions | H7: =COUNT(D7:D256) -> 250
B8: =Calculs!B758 -> 45478 | C8: =Calculs!C758 -> -4612013.4 | D8: =LARGE(Calculs!C508:C757,250-ROUNDUP(ROUND(RL_Confiance*250,9),0)+1) -> 13902951 | E8: =IF(C8>D8,1,0) -> 0 | G8: Exceptions observées | H8: =SUM(E7:E256) -> 4
B9: =Calculs!B759 -> 45481 | C9: =Calculs!C759 -> -5651271.8 | D9: =LARGE(Calculs!C509:C758,250-ROUNDUP(ROUND(RL_Confiance*250,9),0)+1) -> 13902951 | E9: =IF(C9>D9,1,0) -> 0 | G9: Exceptions attendues | H9: =H7*(1-RL_Confiance) -> 2.5
B10: =Calculs!B760 -> 45482 | C10: =Calculs!C760 -> 1287665.8 | D10: =LARGE(Calculs!C510:C759,250-ROUNDUP(ROUND(RL_Confiance*250,9),0)+1) -> 13902951 | E10: =IF(C10>D10,1,0) -> 0 | G10: Statistique de Kupiec (LR) | H10: =-2*((H7-H8)*LN(RL_Confiance)+H8*LN(1-RL_Confiance)-IF(H8=0,0,(H7-H8)*LN(1-H8/H7)+H8*LN(H8/H7))) -> 0.76913836
B11: =Calculs!B761 -> 45483 | C11: =Calculs!C761 -> -1762033.6 | D11: =LARGE(Calculs!C511:C760,250-ROUNDUP(ROUND(RL_Confiance*250,9),0)+1) -> 13902951 | E11: =IF(C11>D11,1,0) -> 0 | G11: p-value (khi-deux, 1 degré) | H11: =CHIDIST(H10,1) -> 0.38048374
B12: =Calculs!B762 -> 45484 | C12: =Calculs!C762 -> -10095480 | D12: =LARGE(Calculs!C512:C761,250-ROUNDUP(ROUND(RL_Confiance*250,9),0)+1) -> 13902951 | E12: =IF(C12>D12,1,0) -> 0 | G12: Conclusion à 5 % | H12: =IF(H11<0.05,"Calibration rejetée","Calibration non rejetée") -> Calibration non rejetée
B13: =Calculs!B763 -> 45485 | C13: =Calculs!C763 -> 3271100.1 | D13: =LARGE(Calculs!C513:C762,250-ROUNDUP(ROUND(RL_Confiance*250,9),0)+1) -> 13902951 | E13: =IF(C13>D13,1,0) -> 0
B14: =Calculs!B764 -> 45488 | C14: =Calculs!C764 -> 3045386.2 | D14: =LARGE(Calculs!C514:C763,250-ROUNDUP(ROUND(RL_Confiance*250,9),0)+1) -> 13902951 | E14: =IF(C14>D14,1,0) -> 0
B15: =Calculs!B765 -> 45489 | C15: =Calculs!C765 -> -7915225.2 | D15: =LARGE(Calculs!C515:C764,250-ROUNDUP(ROUND(RL_Confiance*250,9),0)+1) -> 13902951 | E15: =IF(C15>D15,1,0) -> 0
B16: =Calculs!B766 -> 45490 | C16: =Calculs!C766 -> 4373895.7 | D16: =LARGE(Calculs!C516:C765,250-ROUNDUP(ROUND(RL_Confiance*250,9),0)+1) -> 13902951 | E16: =IF(C16>D16,1,0) -> 0
B17: =Calculs!B767 -> 45491 | C17: =Calculs!C767 -> -6226613.2 | D17: =LARGE(Calculs!C517:C766,250-ROUNDUP(ROUND(RL_Confiance*250,9),0)+1) -> 13902951 | E17: =IF(C17>D17,1,0) -> 0
B18: =Calculs!B768 -> 45492 | C18: =Calculs!C768 -> 7438876.4 | D18: =LARGE(Calculs!C518:C767,250-ROUNDUP(ROUND(RL_Confiance*250,9),0)+1) -> 13902951 | E18: =IF(C18>D18,1,0) -> 0
B19: =Calculs!B769 -> 45495 | C19: =Calculs!C769 -> -5006214.5 | D19: =LARGE(Calculs!C519:C768,250-ROUNDUP(ROUND(RL_Confiance*250,9),0)+1) -> 13902951 | E19: =IF(C19>D19,1,0) -> 0
B20: =Calculs!B770 -> 45496 | C20: =Calculs!C770 -> -843191.08 | D20: =LARGE(Calculs!C520:C769,250-ROUNDUP(ROUND(RL_Confiance*250,9),0)+1) -> 13902951 | E20: =IF(C20>D20,1,0) -> 0
B21: =Calculs!B771 -> 45497 | C21: =Calculs!C771 -> -1302835.6 | D21: =LARGE(Calculs!C521:C770,250-ROUNDUP(ROUND(RL_Confiance*250,9),0)+1) -> 13902951 | E21: =IF(C21>D21,1,0) -> 0
B22: =Calculs!B772 -> 45498 | C22: =Calculs!C772 -> -2771627.2 | D22: =LARGE(Calculs!C522:C771,250-ROUNDUP(ROUND(RL_Confiance*250,9),0)+1) -> 13902951 | E22: =IF(C22>D22,1,0) -> 0
B23: =Calculs!B773 -> 45499 | C23: =Calculs!C773 -> -2307170.4 | D23: =LARGE(Calculs!C523:C772,250-ROUNDUP(ROUND(RL_Confiance*250,9),0)+1) -> 13902951 | E23: =IF(C23>D23,1,0) -> 0
B24: =Calculs!B774 -> 45502 | C24: =Calculs!C774 -> 1893827 | D24: =LARGE(Calculs!C524:C773,250-ROUNDUP(ROUND(RL_Confiance*250,9),0)+1) -> 13902951 | E24: =IF(C24>D24,1,0) -> 0
... B256: =Calculs!B1006 -> 45838 | C256: =Calculs!C1006 -> -1931812.9 | D256: =LARGE(Calculs!C756:C1005,250-ROUNDUP(ROUND(RL_Confiance*250,9),0)+1) -> 16609527 | E256: =IF(C256>D256,1,0) -> 0

Sheet Contrôles
B2: Contrôles et rapprochements
B3: Rapprochements recalculés par formules. Les alertes portent sur l'inventaire publié complet.
B5: Contrôle | C5: Mesure | D5: Attendu | E5: Résultat
B6: Total de l'inventaire = sous-total publié (EUR) | C6: =SUM(Inventaire!$J$7:$J$175) -> 2.5922268e+09 | D6: 2.5922268e+09 | E6: =IF(ABS(C6-D6)<0.02,"OK","ÉCART") -> OK
B7: Somme des poids après vente | C7: =Positions!U175 -> 1 | D7: 1 | E7: =IF(ABS(C7-D7)<0.000000001,"OK","ÉCART") -> OK
B8: Contributions par ligne moins ES après vente (EUR) | C8: =Positions!W175-Calculs!J17 -> 0 | D8: 0 | E8: =IF(ABS(C8-D8)<0.01,"OK","ÉCART") -> OK
B9: Contributions par facteur moins ES après vente (EUR) | C9: =Comité!D29+Comité!D30+Comité!D31+Comité!D32-Calculs!J17 -> 0 | D9: 0 | E9: =IF(ABS(C9-D9)<0.01,"OK","ÉCART") -> OK
B10: Somme des poids de queue après vente | C10: =Calculs!J20 -> 1 | D10: 1 | E10: =IF(ABS(C10-D10)<0.000000001,"OK","ÉCART") -> OK
B11: Flux actualisés moins prix dirty (écart maximal) | C11: =MAX(MAX(Positions!AD7:AD173),-MIN(Positions!AD7:AD173)) -> 0 | D11: 0 | E11: =IF(ABS(C11-D11)<0.000001,"OK","ÉCART") -> OK
B13: Dernière vérification VBA indépendante
B15: Ligne en alerte | C15: ISIN | D15: Suite | E15: Constat
B16: =IFERROR(INDEX(Inventaire!$C$7:$C$175,MATCH(1,Inventaire!$X$7:$X$175,0)),"") -> AGRIPOLE 5.0 11-19 | C16: =IFERROR(INDEX(Inventaire!$B$7:$B$175,MATCH(1,Inventaire!$X$7:$X$175,0)),"") -> FR0012317451 | D16: =IFERROR(INDEX(Inventaire!$W$7:$W$175,MATCH(1,Inventaire!$X$7:$X$175,0)),"") -> À instruire | E16: =IFERROR(TRIM(IF(INDEX(Inventaire!$R$7:$R$175,MATCH(1,Inventaire!$X$7:$X$175,0))="OUI","Titre échu toujours en inventaire. ","")&IF(INDEX(Inventaire!$S$7:$S$175,MATCH(1,Inventaire!$X$7:$X$175,0))="OUI","Valorisation nulle. ","")&IF(INDEX(Inventaire!$T$7:$T$175,MATCH(1,Inventaire!$X$7:$X$175,0))="OUI","Prix daté du "&TEXT(INDEX(Inventaire!$K$7:$K$175,MATCH(1,Inventaire!$X$7:$X$175,0)),"dd/mm/yyyy")&". ","")&IF(INDEX(Inventaire!$U$7:$U$175,MATCH(1,Inventaire!$X$7:$X$175,0))="OUI","Spread calibré de "&TEXT(INDEX(Inventaire!$Q$7:$Q$175,MATCH(1,Inventaire!$X$7:$X$175,0)),"0")&" pb. ","")&IF(INDEX(Inventaire!$V$7:$V$175,MATCH(1,Inventaire!$X$7:$X$175,0))="OUI","Écart de valorisation. ","")),"")
B17: =IFERROR(INDEX(Inventaire!$C$7:$C$175,MATCH(2,Inventaire!$X$7:$X$175,0)),"") -> CMC RAV 2.0 12-26 | C17: =IFERROR(INDEX(Inventaire!$B$7:$B$175,MATCH(2,Inventaire!$X$7:$X$175,0)),"") -> IT0005440646 | D17: =IFERROR(INDEX(Inventaire!$W$7:$W$175,MATCH(2,Inventaire!$X$7:$X$175,0)),"") -> À instruire | E17: =IFERROR(TRIM(IF(INDEX(Inventaire!$R$7:$R$175,MATCH(2,Inventaire!$X$7:$X$175,0))="OUI","Titre échu toujours en inventaire. ","")&IF(INDEX(Inventaire!$S$7:$S$175,MATCH(2,Inventaire!$X$7:$X$175,0))="OUI","Valorisation nulle. ","")&IF(INDEX(Inventaire!$T$7:$T$175,MATCH(2,Inventaire!$X$7:$X$175,0))="OUI","Prix daté du "&TEXT(INDEX(Inventaire!$K$7:$K$175,MATCH(2,Inventaire!$X$7:$X$175,0)),"dd/mm/yyyy")&". ","")&IF(INDEX(Inventaire!$U$7:$U$175,MATCH(2,Inventaire!$X$7:$X$175,0))="OUI","Spread calibré de "&TEXT(INDEX(Inventaire!$Q$7:$Q$175,MATCH(2,Inventaire!$X$7:$X$175,0)),"0")&" pb. ","")&IF(INDEX(Inventaire!$V$7:$V$175,MATCH(2,Inventaire!$X$7:$X$175,0))="OUI","Écart de valorisation. ","")),"") -> Valorisation nulle.
B18: =IFERROR(INDEX(Inventaire!$C$7:$C$175,MATCH(3,Inventaire!$X$7:$X$175,0)),"") -> CONS EN 5.0 10-28 | C18: =IFERROR(INDEX(Inventaire!$B$7:$B$175,MATCH(3,Inventaire!$X$7:$X$175,0)),"") -> XS2393687350 | D18: =IFERROR(INDEX(Inventaire!$W$7:$W$175,MATCH(3,Inventaire!$X$7:$X$175,0)),"") -> À examiner | E18: =IFERROR(TRIM(IF(INDEX(Inventaire!$R$7:$R$175,MATCH(3,Inventaire!$X$7:$X$175,0))="OUI","Titre échu toujours en inventaire. ","")&IF(INDEX(Inventaire!$S$7:$S$175,MATCH(3,Inventaire!$X$7:$X$175,0))="OUI","Valorisation nulle. ","")&IF(INDEX(Inventaire!$T$7:$T$175,MATCH(3,Inventaire!$X$7:$X$175,0))="OUI","Prix daté du "&TEXT(INDEX(Inventaire!$K$7:$K$175,MATCH(3,Inventaire!$X$7:$X$175,0)),"dd/mm/yyyy")&". ","")&IF(INDEX(Inventaire!$U$7:$U$175,MATCH(3,Inventaire!$X$7:$X$175,0))="OUI","Spread calibré de "&TEXT(INDEX(Inventaire!$Q$7:$Q$175,MATCH(3,Inventaire!$X$7:$X$175,0)),"0")&" pb. ","")&IF(INDEX(Inventaire!$V$7:$V$175,MATCH(3,Inventaire!$X$7:$X$175,0))="OUI","Écart de valorisation. ","")),"") -> Spread calibré de 881 pb.
B19: =IFERROR(INDEX(Inventaire!$C$7:$C$175,MATCH(4,Inventaire!$X$7:$X$175,0)),"") -> IM GROU 8.0 03-28 | C19: =IFERROR(INDEX(Inventaire!$B$7:$B$175,MATCH(4,Inventaire!$X$7:$X$175,0)),"") -> XS2587104444 | D19: =IFERROR(INDEX(Inventaire!$W$7:$W$175,MATCH(4,Inventaire!$X$7:$X$175,0)),"") -> À examiner | E19: =IFERROR(TRIM(IF(INDEX(Inventaire!$R$7:$R$175,MATCH(4,Inventaire!$X$7:$X$175,0))="OUI","Titre échu toujours en inventaire. ","")&IF(INDEX(Inventaire!$S$7:$S$175,MATCH(4,Inventaire!$X$7:$X$175,0))="OUI","Valorisation nulle. ","")&IF(INDEX(Inventaire!$T$7:$T$175,MATCH(4,Inventaire!$X$7:$X$175,0))="OUI","Prix daté du "&TEXT(INDEX(Inventaire!$K$7:$K$175,MATCH(4,Inventaire!$X$7:$X$175,0)),"dd/mm/yyyy")&". ","")&IF(INDEX(Inventaire!$U$7:$U$175,MATCH(4,Inventaire!$X$7:$X$175,0))="OUI","Spread calibré de "&TEXT(INDEX(Inventaire!$Q$7:$Q$175,MATCH(4,Inventaire!$X$7:$X$175,0)),"0")&" pb. ","")&IF(INDEX(Inventaire!$V$7:$V$175,MATCH(4,Inventaire!$X$7:$X$175,0))="OUI","Écart de valorisation. ","")),"") -> Spread calibré de 2912 pb.
B20: =IFERROR(INDEX(Inventaire!$C$7:$C$175,MATCH(5,Inventaire!$X$7:$X$175,0)),"") -> INTL PE 10.75 12-29 | C20: =IFERROR(INDEX(Inventaire!$B$7:$B$175,MATCH(5,Inventaire!$X$7:$X$175,0)),"") -> XS2835773255 | D20: =IFERROR(INDEX(Inventaire!$W$7:$W$175,MATCH(5,Inventaire!$X$7:$X$175,0)),"") -> À examiner | E20: =IFERROR(TRIM(IF(INDEX(Inventaire!$R$7:$R$175,MATCH(5,Inventaire!$X$7:$X$175,0))="OUI","Titre échu toujours en inventaire. ","")&IF(INDEX(Inventaire!$S$7:$S$175,MATCH(5,Inventaire!$X$7:$X$175,0))="OUI","Valorisation nulle. ","")&IF(INDEX(Inventaire!$T$7:$T$175,MATCH(5,Inventaire!$X$7:$X$175,0))="OUI","Prix daté du "&TEXT(INDEX(Inventaire!$K$7:$K$175,MATCH(5,Inventaire!$X$7:$X$175,0)),"dd/mm/yyyy")&". ","")&IF(INDEX(Inventaire!$U$7:$U$175,MATCH(5,Inventaire!$X$7:$X$175,0))="OUI","Spread calibré de "&TEXT(INDEX(Inventaire!$Q$7:$Q$175,MATCH(5,Inventaire!$X$7:$X$175,0)),"0")&" pb. ","")&IF(INDEX(Inventaire!$V$7:$V$175,MATCH(5,Inventaire!$X$7:$X$175,0))="OUI","Écart de valorisation. ","")),"") -> Spread calibré de 670 pb.
B21: =IFERROR(INDEX(Inventaire!$C$7:$C$175,MATCH(6,Inventaire!$X$7:$X$175,0)),"") -> ASK CHE 10.0 11-29 | C21: =IFERROR(INDEX(Inventaire!$B$7:$B$175,MATCH(6,Inventaire!$X$7:$X$175,0)),"") -> XS2919072962 | D21: =IFERROR(INDEX(Inventaire!$W$7:$W$175,MATCH(6,Inventaire!$X$7:$X$175,0)),"") -> À examiner | E21: =IFERROR(TRIM(IF(INDEX(Inventaire!$R$7:$R$175,MATCH(6,Inventaire!$X$7:$X$175,0))="OUI","Titre échu toujours en inventaire. ","")&IF(INDEX(Inventaire!$S$7:$S$175,MATCH(6,Inventaire!$X$7:$X$175,0))="OUI","Valorisation nulle. ","")&IF(INDEX(Inventaire!$T$7:$T$175,MATCH(6,Inventaire!$X$7:$X$175,0))="OUI","Prix daté du "&TEXT(INDEX(Inventaire!$K$7:$K$175,MATCH(6,Inventaire!$X$7:$X$175,0)),"dd/mm/yyyy")&". ","")&IF(INDEX(Inventaire!$U$7:$U$175,MATCH(6,Inventaire!$X$7:$X$175,0))="OUI","Spread calibré de "&TEXT(INDEX(Inventaire!$Q$7:$Q$175,MATCH(6,Inventaire!$X$7:$X$175,0)),"0")&" pb. ","")&IF(INDEX(Inventaire!$V$7:$V$175,MATCH(6,Inventaire!$X$7:$X$175,0))="OUI","Écart de valorisation. ","")),"") -> Spread calibré de 857 pb.
B22: =IFERROR(INDEX(Inventaire!$C$7:$C$175,MATCH(7,Inventaire!$X$7:$X$175,0)),"") | C22: =IFERROR(INDEX(Inventaire!$B$7:$B$175,MATCH(7,Inventaire!$X$7:$X$175,0)),"") | D22: =IFERROR(INDEX(Inventaire!$W$7:$W$175,MATCH(7,Inventaire!$X$7:$X$175,0)),"") | E22: =IFERROR(TRIM(IF(INDEX(Inventaire!$R$7:$R$175,MATCH(7,Inventaire!$X$7:$X$175,0))="OUI","Titre échu toujours en inventaire. ","")&IF(INDEX(Inventaire!$S$7:$S$175,MATCH(7,Inventaire!$X$7:$X$175,0))="OUI","Valorisation nulle. ","")&IF(INDEX(Inventaire!$T$7:$T$175,MATCH(7,Inventaire!$X$7:$X$175,0))="OUI","Prix daté du "&TEXT(INDEX(Inventaire!$K$7:$K$175,MATCH(7,Inventaire!$X$7:$X$175,0)),"dd/mm/yyyy")&". ","")&IF(INDEX(Inventaire!$U$7:$U$175,MATCH(7,Inventaire!$X$7:$X$175,0))="OUI","Spread calibré de "&TEXT(INDEX(Inventaire!$Q$7:$Q$175,MATCH(7,Inventaire!$X$7:$X$175,0)),"0")&" pb. ","")&IF(INDEX(Inventaire!$V$7:$V$175,MATCH(7,Inventaire!$X$7:$X$175,0))="OUI","Écart de valorisation. ","")),"")
B23: =IFERROR(INDEX(Inventaire!$C$7:$C$175,MATCH(8,Inventaire!$X$7:$X$175,0)),"") | C23: =IFERROR(INDEX(Inventaire!$B$7:$B$175,MATCH(8,Inventaire!$X$7:$X$175,0)),"") | D23: =IFERROR(INDEX(Inventaire!$W$7:$W$175,MATCH(8,Inventaire!$X$7:$X$175,0)),"") | E23: =IFERROR(TRIM(IF(INDEX(Inventaire!$R$7:$R$175,MATCH(8,Inventaire!$X$7:$X$175,0))="OUI","Titre échu toujours en inventaire. ","")&IF(INDEX(Inventaire!$S$7:$S$175,MATCH(8,Inventaire!$X$7:$X$175,0))="OUI","Valorisation nulle. ","")&IF(INDEX(Inventaire!$T$7:$T$175,MATCH(8,Inventaire!$X$7:$X$175,0))="OUI","Prix daté du "&TEXT(INDEX(Inventaire!$K$7:$K$175,MATCH(8,Inventaire!$X$7:$X$175,0)),"dd/mm/yyyy")&". ","")&IF(INDEX(Inventaire!$U$7:$U$175,MATCH(8,Inventaire!$X$7:$X$175,0))="OUI","Spread calibré de "&TEXT(INDEX(Inventaire!$Q$7:$Q$175,MATCH(8,Inventaire!$X$7:$X$175,0)),"0")&" pb. ","")&IF(INDEX(Inventaire!$V$7:$V$175,MATCH(8,Inventaire!$X$7:$X$175,0))="OUI","Écart de valorisation. ","")),"")
B24: =IFERROR(INDEX(Inventaire!$C$7:$C$175,MATCH(9,Inventaire!$X$7:$X$175,0)),"") | C24: =IFERROR(INDEX(Inventaire!$B$7:$B$175,MATCH(9,Inventaire!$X$7:$X$175,0)),"") | D24: =IFERROR(INDEX(Inventaire!$W$7:$W$175,MATCH(9,Inventaire!$X$7:$X$175,0)),"") | E24: =IFERROR(TRIM(IF(INDEX(Inventaire!$R$7:$R$175,MATCH(9,Inventaire!$X$7:$X$175,0))="OUI","Titre échu toujours en inventaire. ","")&IF(INDEX(Inventaire!$S$7:$S$175,MATCH(9,Inventaire!$X$7:$X$175,0))="OUI","Valorisation nulle. ","")&IF(INDEX(Inventaire!$T$7:$T$175,MATCH(9,Inventaire!$X$7:$X$175,0))="OUI","Prix daté du "&TEXT(INDEX(Inventaire!$K$7:$K$175,MATCH(9,Inventaire!$X$7:$X$175,0)),"dd/mm/yyyy")&". ","")&IF(INDEX(Inventaire!$U$7:$U$175,MATCH(9,Inventaire!$X$7:$X$175,0))="OUI","Spread calibré de "&TEXT(INDEX(Inventaire!$Q$7:$Q$175,MATCH(9,Inventaire!$X$7:$X$175,0)),"0")&" pb. ","")&IF(INDEX(Inventaire!$V$7:$V$175,MATCH(9,Inventaire!$X$7:$X$175,0))="OUI","Écart de valorisation. ","")),"")
